Calling a function with a repeated keyword argument will result in an exception:

    kwargs = {'a': 24}
    foo(a=42, **kwargs)